Workbook

Sheet README
A1: NAVIER × MARTI — TÜRKIYE NETWORK MODEL
A2: How to read this workbook
A3: This is the companion financial model to the Navier × Marti go-to-market agreement. It is shared with Marti as a partner — every tab is meant to be readable without a walkthrough call.
A5: COLOR KEY
A6: Blue text | B6: An input assumption — change it and the model recalculates.
A7: Yellow fill | B7: A key scenario output — the headline number for that section.
A8: Black text | B8: A calculated formula. No need to edit.
A9: Green text | B9: Pulled live from another tab (used sparingly; most cross-tab pulls are black formulas referencing another sheet).
A11: WHERE TO START
A12: Five-minute read | B12: Dashboard — one page, headline numbers only, pulls from every other tab.
A13: Evaluating whether Marti should own boats | B13: Marti Asset Holder P&L — year-by-year P&L if Marti owns a tranche of the fleet, vs. staying platform-only.
A14: Checking the math behind a number | B14: Start at Assumptions, then the relevant per-vessel tab (N30 Experience / N25 Shuttle) — every downstream tab traces back to these.
A16: TAB-BY-TAB GUIDE
A17: Tab | B17: What it shows | C17: Key output
A19: Dashboard | B19: One-page snapshot of the headline numbers from every tab below. | C19: Paybacks, fleet size, Marti revenue, ownership rungs
A20: Assumptions | B20: The editable inputs driving the whole model: market sizing, platform take rates, payback targets. | C20: Marti take 15% / Navier Platform Fee 10% of GMV
A21: N30 Experience | B21: Per-boat annual P&L and payback for the premium experience yacht — pricing ladder, seasonal utilization, opex. | C21: Payback: 1.37 yrs base / 0.94 yrs target
A22: N25 Shuttle | B22: Per-boat annual P&L and payback for the volume shuttle, plus the autonomy-stage margin engine (crewed → remote supervision). | C22: Payback: 1.64 yrs crewed / 1.43 yrs autonomous
A23: Fleet Sizing | B23: How the market-demand assumptions translate into the 2028 steady-state fleet size. | C23: 233 vessels, $87.5M hardware TAM
A24: Fleet Ramp & Booking Revenue Forecast | B24: Year-by-year (2027–2030) fleet build-out, total network GMV, and Marti's own booking revenue. | C24: $95M network GMV / $10.7M Marti revenue by 2030
A25: Profitability per Boat by Owner | B25: Who profits from owning a boat — 3rd-party owner vs. Marti-owned — and Marti's 3 ownership 'rungs' (platform-only / launch-fleet owner / SPV co-owner). | C25: Rung 2 net profit: $16.8M (2029), 83.9% ROIC
A26: Marti Asset Holder P&L | B26: Year-by-year forecast of Marti's own P&L if it chooses to own a tranche of the fleet — spread over the build-out, not a single-year snapshot. | C26: +$10.2M/yr incremental profit vs. platform-only, once phased in
A27: Sensitivity | B27: Stress-tests payback against realistic swings in utilization/pricing (N30) and load factor/fare (N25). | C27: Payback sensitivity grids
A28: 2026 Validation | B28: How demand gets proven before a single hull ships in Türkiye — the 4 tracks (Marti data-sharing, hotel LOIs, deposit-backed waitlist, demos) and the MOU exclusivity terms. | C28: 9 implied committed hulls vs. the 10-boat launch fleet

Sheet Dashboard
A1: NAVIER × MARTI — MODEL DASHBOARD
A2: All figures recalculate from Assumptions and per-vessel tabs. Change any blue cell; this page updates.
A4: PER-VESSEL ECONOMICS
A5: N30 Experience payback — Base (yrs) | B5: ='N30 Experience'!C37 -> 1.3697362
A6: N30 Experience payback — Target (yrs) | B6: ='N30 Experience'!D37 -> 0.94160061
A7: Realized $/day needed for 1.0-yr N30 payback | B7: ='N30 Experience'!B39 -> 8187.8329
A8: N25 Shuttle payback — crewed (yrs) | B8: ='N25 Shuttle'!B30 -> 1.6356118
A9: N25 Shuttle payback — remote supervision (yrs) | B9: ='N25 Shuttle'!E36 -> 1.4257363
A10: N25 margin — crewed → autonomous | B10: ='N25 Shuttle'!B29 -> 0.54839265 | C10: ='N25 Shuttle'!D36 -> 0.62911883
A12: FLEET & MARKET (2028)
A13: Türkiye fleet | B13: ='Fleet Sizing'!B24 -> 233
A14: Hardware TAM | B14: ='Fleet Sizing'!B27 -> 87500000
A15: 2028 network GMV | B15: ='Fleet Ramp & Booking Revenue Fo'!C10 -> 36480400
A16: 2028 Marti booking revenue | B16: ='Fleet Ramp & Booking Revenue Fo'!C12 -> 4104045
A17: 2028 Marti rev vs their 2026 guidance | B17: ='Fleet Ramp & Booking Revenue Fo'!C13 -> 0.058629214
A18: Cumulative fleet by end-2029 / end-2030 (units) | B18: ='Fleet Ramp & Booking Revenue Fo'!D18 -> 132 | C18: ='Fleet Ramp & Booking Revenue Fo'!E18 -> 207
A19: 2026 VALIDATION (NO MARKETPLACE)
A20: Hotel LOIs target / implied committed hulls | B20: ='2026 Validation'!B10 -> 6 | C20: ='2026 Validation'!B12 -> 9
A21: Waitlist deposits escrowed | B21: ='2026 Validation'!B18 -> 250000
A22: Bidirectional exclusivity term (yrs) | B22: ='2026 Validation'!B29 -> 4
A24: MARTI OWNERSHIP (2029)
A25: Rung 1 — platform only, net profit | B25: ='Profitability per Boat by Owner'!D20 -> 6584615.5
A26: Rung 2 — launch-fleet owner, net profit / ROIC | B26: ='Profitability per Boat by Owner'!D21 -> 16789542 | C26: ='Profitability per Boat by Owner'!E21 -> 0.8394771
A27: Rung 3 — SPV co-owner (50%), net profit / ROIC | B27: ='Profitability per Boat by Owner'!D22 -> 20039547 | C27: ='Profitability per Boat by Owner'!E22 -> 0.60043588
A29: REVENUE SCENARIOS & MARTI TAKE (utilization is the only lever)
A30: Selected scenario (toggle on Assumptions) | B30: =Assumptions!B29 -> Aggressive | C30: util × | D30: =Assumptions!B30 -> 1
A31: Scenario | B31: Utilization × | C31: Asset-holder payback @ current take | D31: @ Marti’s 30% take
A32: Aggressive | B32: =Assumptions!B25 -> 1 | C32: =Sensitivity!B30 -> 1.6752303 | D32: =Sensitivity!B33 -> 2.1561106
A33: Moderate | B33: =Assumptions!B26 -> 0.75 | C33: =Sensitivity!C30 -> 2.5034445 | D33: =Sensitivity!C33 -> 3.3377996
A34: Conservative | B34: =Assumptions!B27 -> 0.55 | C34: =Sensitivity!D30 -> 4.1414201 | D34: =Sensitivity!D33 -> 5.9439266
A36: Binding case — Conservative @ 30% take payback (yrs) | B36: =Sensitivity!D33 -> 5.9439266
A37: Marti take needed for ≤4-yr payback (Conservative) | B37: =Sensitivity!B46 -> 0.13251205
A38: …or revenue guarantee ($/N30/yr, take held 30%) | B38: =Sensitivity!B49 -> 798198.2

Sheet Assumptions
A1: NAVIER × MARTI — TÜRKIYE NETWORK MODEL
A2: All blue cells are inputs you can change. Yellow = key scenario levers. Black = formulas. Green = pulls from another tab.
A3: Example input row format: enter plain numbers (19000000, not 19M); percentages as decimals shown as % (0.15 → 15%).
A5: MARKET (source: T.C. Ministry of Culture & Tourism via Daily Sabah / Anadolu, 2025 actuals)
A6: Istanbul foreign visitors / yr | B6: 19000000 | C6: 16.01M Jan–Oct 2025, annualized
A7: Premium traveler share | B7: 0.15 | C7: 5★-skewed overnight mix in official stats
A8: Experience capture rate at scale (2028) | B8: 0.08 | C8: share of premium visitors buying 1 water experience
A9: Average party size (pax / booking) | B9: 5
A10: Affluent Istanbul households (top 3%) | B10: 165000 | C10: ~5.5M households × 3%
A11: Local household purchase rate / yr | B11: 0.2
A12: Coastal markets multiplier (× Istanbul demand) | B12: 1.5 | C12: Bodrum/Antalya/Fethiye; Antalya = 32.5% of arrivals
A14: PLATFORM ECONOMICS
A15: Marti app booking share of GMV | B15: 0.75
A16: Marti take rate (% of Marti booked GMV) | B16: 0.15
A17: Navier Platform Fee (% of total GMV) | B17: 0.1 | C17: Fleet mgmt software, experiences mgmt, remote diagnostics, OTA/continuous updates, captain app, multichannel booking, analytics, etc
A19: TARGETS
A20: Experience vessel payback target (yrs) | B20: 1
A21: Shuttle vessel payback target (yrs) | B21: 1.5
A23: SCENARIOS — UTILIZATION (the only lever that changes across cases)
A24: Scenario | B24: Utilization × (vs Aggressive) | C24: Note
A25: Aggressive | B25: 1 | C25: current base case (unchanged)
A26: Moderate | B26: 0.75 | C26: −25% utilization
A27: Conservative | B27: 0.55 | C27: −45% utilization
A29: SELECTED SCENARIO (toggle) → | B29: Aggressive
A30: Selected utilization multiplier | B30: =INDEX(B25:B27,MATCH(B29,A25:A27,0)) -> 1

Sheet N30 Experience
A1: N30 PIONEER II — 'ALWAYS OPERATING' EXPERIENCE MODEL
A2: One boat, one day, five sellable slots. Utilization (share of slot revenue realized, incl. dynamic pricing) is the master lever.
A4: Vessel capex | B4: 1000000
A6: DAILY PRODUCT LADDER (per-slot pricing — dynamic, app-adjusted)
A7: Product | B7: Price | C7: Pax / groups | D7: Pricing basis | E7: Gross / slot
A8: Morning Foil Experience (45 min, learn-to-foil) | B8: 95 | C8: 6 | D8: per seat | E8: =B8*C8 -> 570
A9: Midday Picnic Charter (3 hr, catered) | B9: 2000 | C9: 1 | D9: per group | E9: =B9*C9 -> 2000
A10: Golden Hour Cruise (90 min) | B10: 120 | C10: 8 | D10: per seat | E10: =B10*C10 -> 960
A11: Sunset Dinner Charter (2.5 hr, incl. F&B) | B11: 3200 | C11: 1 | D11: per group | E11: =B11*C11 -> 3200
A12: Night Skyline Cruise (60 min) | B12: 95 | C12: 8 | D12: per seat | E12: =B12*C12 -> 760
A13: Full-day revenue potential | E13: =SUM(E8:E12) -> 7490
A15: SEASONAL UTILIZATION → DAY-EQUIVALENTS
A16: Season | B16: Days | C16: Utilization (Base) | D16: Utilization (Target)
A17: Peak (Jun–Sep) | B17: 120 | C17: 0.75 | D17: 0.85
A18: Shoulder (Apr–May, Oct) | B18: 100 | C18: 0.5 | D18: 0.62
A19: Low (Nov–Mar, event/holiday only) | B19: 60 | C19: 0.3 | D19: 0.38
A20: Revenue day-equivalents | C20: =SUMPRODUCT($B$17:$B$19,C17:C19) -> 158 | D20: =SUMPRODUCT($B$17:$B$19,D17:D19) -> 186.8
A21: Dynamic pricing uplift (Target only: live pricing, holiday & event premiums) | D21: 0.15
A22: ANNUAL P&L PER VESSEL
C23: Selected | D23: Stretch ref
A24: Gross revenue | C24: =$E$13*C20*Assumptions!$B$30 -> 1183420 | D24: =$E$13*D20*(1+$D$21) -> 1609001.8
A25: F&B / experience provisioning (% rev) | B25: 0.12 | C25: =-C24*$B$25 -> -142010.4 | D25: =-D24*$B$25 -> -193080.22
A26: Navier Platform Fee (% of GMV) | B26: =Assumptions!$B$17 -> 0.1 | C26: =-C24*$B$26 -> -118342 | D26: =-D24*$B$26 -> -160900.18
A27: Crew (captain + host) | B27: -65000
A28: Energy (electric) | B28: -18000
A29: Dockage / marina | B29: -30000
A30: Maintenance reserve (3% capex) | B30: =-$B$4*0.03 -> -30000
A31: Insurance (2% capex) | B31: =-$B$4*0.02 -> -20000
A32: Turnaround, cleaning, consumables | B32: -12000
A33: Ops management allocation (dispatch, support, shore staff) | B33: -18000
A34: Total fixed opex | B34: =SUM(B27:B33) -> -193000
A35: Contribution | C35: =C24+C25+C26+$B$34 -> 730067.6 | D35: =D24+D25+D26+$B$34 -> 1062021.4
A36: Operating margin | C36: =C35/C24 -> 0.61691335 | D36: =D35/D24 -> 0.66004985
A37: PAYBACK (yrs) | C37: =$B$4/C35 -> 1.3697362 | D37: =$B$4/D35 -> 0.94160061
A38: (Scenario multiplier applies to the Selected column; Stretch = fixed 0.85-util upside reference.)
A39: Realized $/day-equivalent needed for 1.0-yr payback | B39: =($B$4-$B$34)/(D20*(1-$B$25-$B$26))/1 -> 8187.8329 | C39: compare vs full-day potential: | D39: =$E$13 -> 7490

Sheet N25 Shuttle
A1: N25 — 26-FT ALUMINUM FOILING SHUTTLE (VOLUME PRODUCT)
A2: Target: payback < 1.5 yrs via utilization + reliability. Autonomy stages show the margin engine.
A4: Vessel capex | B4: 250000
A6: SHUTTLE OPERATING ASSUMPTIONS
A7: Fare per seat | B7: 14
A8: Seats | B8: 8
A9: Legs per day | B9: 14
A10: Load factor | B10: 0.55
A11: Operating days / yr | B11: 300
A12: Evening charter nights / yr | B12: 40
A13: Evening charter price | B13: 500
A15: Daily shuttle revenue | B15: =B7*B8*B9*B10 -> 862.4
A16: Annual gross revenue | B16: =B15*B11*Assumptions!$B$30+B12*B13 -> 278720
A18: ANNUAL OPEX
A19: Captain (Stage 0: crewed) | B19: -30000
A20: Energy | B20: -14000
A21: Dockage | B21: -18000
A22: Maintenance (4% capex) | B22: =-$B$4*0.04 -> -10000
A23: Insurance | B23: -6000
A24: Cleaning & misc | B24: -8000
A25: Ops management allocation (dispatch, support) | B25: -12000
A26: Navier Platform Fee (% of GMV) | B26: =-B16*Assumptions!$B$17 -> -27872
A27: Total opex | B27: =SUM(B19:B26) -> -125872
A28: Contribution | B28: =B16+B27 -> 152848
A29: Operating margin | B29: =B28/B16 -> 0.54839265
A30: PAYBACK (yrs) | B30: =B4/B28 -> 1.6356118
A32: AUTONOMY STAGES — MARGIN ENGINE (WITHOUT → WITH AUTONOMY)
A33: Stage | B33: Crew cost / boat | C33: Contribution | D33: Margin | E33: Payback (yrs)
A34: Stage 0 — Crewed (today) | B34: =$B$19*1 -> -30000 | C34: =$B$28-$B$19+B34 -> 152848 | D34: =C34/$B$16 -> 0.54839265 | E34: =$B$4/C34 -> 1.6356118
A35: Stage 1 — Remote-assist, reduced crew hrs (−30%) | B35: =$B$19*0.7 -> -21000 | C35: =$B$28-$B$19+B35 -> 161848 | D35: =C35/$B$16 -> 0.58068312 | E35: =$B$4/C35 -> 1.5446592
A36: Stage 2 — Remote supervision 1 operator : 4 boats | B36: =$B$19*0.25 -> -7500 | C36: =$B$28-$B$19+B36 -> 175348 | D36: =C36/$B$16 -> 0.62911883 | E36: =$B$4/C36 -> 1.4257363
A38: Note: Stage 2 also enables ~20% fare cut at constant margin — the bridge from premium to Marti's mass demographic.

Sheet Fleet Sizing
A1: DEMAND → FLEET SIZING (2028 STEADY STATE)
A3: EXPERIENCE FLEET
A4: Istanbul premium visitors / yr | B4: =Assumptions!B6*Assumptions!B7 -> 2850000
A5: Tourist experience pax captured | B5: =B4*Assumptions!B8 -> 228000
A6: Local affluent bookings / yr | B6: =Assumptions!B10*Assumptions!B11 -> 33000
A7: Tourist bookings (pax ÷ party size) | B7: =B5/Assumptions!B9 -> 45600
A8: Total Istanbul experience bookings | B8: =B6+B7 -> 78600
A9: Slots per boat per yr (day-equivalents × 5 slots) | B9: ='N30 Experience'!D20*5 -> 934
A10: Istanbul experience boats needed | B10: =ROUNDUP(B8/B9,0) -> 85
A11: Türkiye experience boats (× coastal mult.) | B11: =ROUNDUP(B10*Assumptions!B12,0) -> 128
A12: N30 flagship share of experience fleet | B12: 0.3
A13: N30 units | B13: =ROUNDUP(B11*B12,0) -> 39
A14: N25-Experience units | B14: =B11-B13 -> 89
A16: SHUTTLE FLEET
A17: Istanbul premium seats / day target (2028) | B17: 4000
A18: Seats per boat per day | B18: ='N25 Shuttle'!B8*'N25 Shuttle'!B9*'N25 Shuttle'!B10 -> 61.6
A19: Istanbul shuttle boats needed | B19: =ROUNDUP(B17/B18,0) -> 65
A20: Coastal / İzmir / hotel shuttle boats | B20: 40
A21: Türkiye shuttle boats | B21: =B19+B20 -> 105
A23: TOTAL FLEET & HARDWARE TAM
A24: Total vessels (2028 network) | B24: =B11+B21 -> 233
A25: N30 price | B25: ='N30 Experience'!B4 -> 1000000
A26: N25 price | B26: ='N25 Shuttle'!B4 -> 250000
A27: Hardware TAM ($) | B27: =B13*B25+(B14+B21)*B26 -> 87500000

Sheet Fleet Ramp & Booking Revenue Fo
A1: NETWORK GMV & MARTI ECONOMICS, 2027–2030
A2: Boats in service = average over the year, not year-end. Blue = ramp inputs. Ramp: ≥100 cumulative units by 2029, ~200 by 2030.
B4: 2027 | C4: 2028 | D4: 2029 | E4: 2030
A5: Experience boats in service (CY avg) — all N30 through 2028 | B5: 12 | C5: 28 | D5: 42 | E5: 52
A6: Shuttle boats in service (avg) — N25 prototypes 2027, scale 2029–30 | B6: 0 | C6: 12 | D6: 55 | E6: 120
A7: Experience GMV / boat | B7: ='N30 Experience'!C24*$B$8 -> 1183420 | C7: =$B$7 -> 1183420 | D7: =$B$7 -> 1183420 | E7: =$B$7 -> 1183420
A8: Fleet factor (1.00 = all-N30 experience fleet) | B8: 1
A9: Shuttle GMV / boat | B9: ='N25 Shuttle'!B16 -> 278720 | C9: =$B$9 -> 278720 | D9: =$B$9 -> 278720 | E9: =$B$9 -> 278720
A10: Total network GMV | B10: =B5*$B$7+B6*$B$9 -> 14201040 | C10: =C5*$B$7+C6*$B$9 -> 36480400 | D10: =D5*$B$7+D6*$B$9 -> 65033240 | E10: =E5*$B$7+E6*$B$9 -> 94984240
A11: GMV booked via Marti app | B11: =B10*Assumptions!$B$15 -> 10650780 | C11: =C10*Assumptions!$B$15 -> 27360300 | D11: =D10*Assumptions!$B$15 -> 48774930 | E11: =E10*Assumptions!$B$15 -> 71238180
A12: MARTI BOOKING REVENUE | B12: =B11*Assumptions!$B$16 -> 1597617 | C12: =C11*Assumptions!$B$16 -> 4104045 | D12: =D11*Assumptions!$B$16 -> 7316239.5 | E12: =E11*Assumptions!$B$16 -> 10685727
A13: vs. Marti 2026 revenue guidance ($70M) | B13: =B12/70000000 -> 0.0228231 | C13: =C12/70000000 -> 0.058629214 | D13: =D12/70000000 -> 0.10451771 | E13: =E12/70000000 -> 0.15265324
A15: Fleet investment (units added × price) | B15: =B16*'N30 Experience'!$B$4+B17*'N25 Shuttle'!$B$4 -> 20500000 | C15: =C16*'N30 Experience'!$B$4+C17*'N25 Shuttle'!$B$4 -> 21250000 | D15: =D16*'N30 Experience'!$B$4+D17*'N25 Shuttle'!$B$4 -> 25000000 | E15: =E16*'N30 Experience'!$B$4+E17*'N25 Shuttle'!$B$4 -> 26250000
A16: N30 units added | B16: 20 | C16: 15 | D16: 10 | E16: 10
A17: N25 units added | B17: 2 | C17: 25 | D17: 60 | E17: 65
A18: CUMULATIVE FLEET (total units delivered) | B18: =B16+B17 -> 22 | C18: =B18+C16+C17 -> 62 | D18: =C18+D16+D17 -> 132 | E18: =D18+E16+E17 -> 207
A20: MILESTONES (context — see agreement doc §6)
A21: 2026 | B21: MOU + announcement; validation program (data clause, hotel LOIs, deposit waitlist); permitting groundwork
A22: 2027 | B22: Navier Experience live (Mar); hotel partnerships; first operating data
A23: 2028 | B23: Shuttle corridors open; Bodrum season; autonomy Stage 1
A24: 2029 | B24: Four-coast network; autonomy Stage 2 — ≥100-vessel milestone hit
A25: 2030 | B25: ~200-vessel network; ferry program design (40-ft, 20–40 pax)

Sheet Profitability per Boat by Owner
A1: OPERATOR ECONOMICS & MARTI OWNERSHIP SCENARIOS
A2: Fully loaded owner P&L: the Navier Platform Fee is already netted into Contribution on the per-vessel tabs. This sheet layers on Marti's take, which applies only to 3rd-party owners.
A3: Pre-tax, pre-financing; excludes network overhead beyond per-boat ops allocation. If the Marti take is charged ON TOP of fares (booking fee), 3rd-party columns improve toward contribution-level paybacks.
A5: PER-BOAT OWNER P&L (annual, steady state)
B6: N30 — 3rd-party owner | C6: N30 — Marti-owned | D6: N25 — 3rd-party owner | E6: N25 — Marti-owned
A7: Gross revenue (GMV) | B7: ='N30 Experience'!C24 -> 1183420 | C7: =B7 -> 1183420 | D7: ='N25 Shuttle'!B16 -> 278720 | E7: =D7 -> 278720
A8: Contribution after direct opex | B8: ='N30 Experience'!C35 -> 730067.6 | C8: =B8 -> 730067.6 | D8: ='N25 Shuttle'!B28 -> 152848 | E8: =D8 -> 152848
A9: (Navier Platform Fee — already included in Contribution above) | B9: 0 | C9: 0 | D9: 0 | E9: 0
A10: Marti take (15% on 75% app-originated GMV) | B10: =-B7*Assumptions!$B$15*Assumptions!$B$16 -> -133134.75 | C10: 0 | D10: =-D7*Assumptions!$B$15*Assumptions!$B$16 -> -31356 | E10: 0
A11: Operating profit | B11: =B8+B9+B10 -> 596932.85 | C11: =C8+C9+C10 -> 730067.6 | D11: =D8+D9+D10 -> 121492 | E11: =E8+E9+E10 -> 152848
A12: Depreciation (10-yr straight line) | B12: =-'N30 Experience'!$B$4/10 -> -100000 | C12: =B12 -> -100000 | D12: =-'N25 Shuttle'!$B$4/10 -> -25000 | E12: =D12 -> -25000
A13: NET PROFIT / boat / yr | B13: =B11+B12 -> 496932.85 | C13: =C11+C12 -> 630067.6 | D13: =D11+D12 -> 96492 | E13: =E11+E12 -> 127848
A14: Net margin | B14: =B13/B7 -> 0.4199125 | C14: =C13/C7 -> 0.5324125 | D14: =D13/D7 -> 0.3461969 | E14: =E13/E7 -> 0.4586969
A15: Cash payback (yrs, capex / operating profit) | B15: ='N30 Experience'!$B$4/B11 -> 1.6752303 | C15: ='N30 Experience'!$B$4/C11 -> 1.3697362 | D15: ='N25 Shuttle'!$B$4/D11 -> 2.0577487 | E15: ='N25 Shuttle'!$B$4/E11 -> 1.6356118
A16: 10-yr cumulative net profit per $1 of capex | B16: =B13*10/'N30 Experience'!$B$4 -> 4.9693285 | C16: =C13*10/'N30 Experience'!$B$4 -> 6.300676 | D16: =D13*10/'N25 Shuttle'!$B$4 -> 3.85968 | E16: =E13*10/'N25 Shuttle'!$B$4 -> 5.11392
A18: MARTI OWNERSHIP RUNGS — 2029 NETWORK
A19: Rung | B19: Capex | C19: 2029 revenue touched | D19: 2029 net profit to Marti | E19: ROIC
A20: 1. Platform only (booking take, zero fleet risk) | B20: 0 | C20: ='Fleet Ramp & Booking Revenue Fo'!D12 -> 7316239.5 | D20: ='Fleet Ramp & Booking Revenue Fo'!D12*0.9 -> 6584615.5 | E20: n/a
A21: 2. Launch-fleet owner (Marti owns the 20 launch N30s) | B21: =20*'N30 Experience'!$B$4 -> 20000000 | C21: ='Fleet Ramp & Booking Revenue Fo'!D10 -> 65033240 | D21: =20*C13+('Fleet Ramp & Booking Revenue Fo'!D10-20*C7)*Assumptions!$B$15*Assumptions!$B$16*0.9 -> 16789542 | E21: =D21/B21 -> 0.8394771
A22: 3. SPV co-owner (50% of fleet w/ Navier + 3rd-party capital) | B22: =0.5*(('Fleet Ramp & Booking Revenue Fo'!B16+'Fleet Ramp & Booking Revenue Fo'!C16+'Fleet Ramp & Booking Revenue Fo'!D16)*'N30 Experience'!$B$4+('Fleet Ramp & Booking Revenue Fo'!B17+'Fleet Ramp & Booking Revenue Fo'!C17+'Fleet Ramp & Booking Revenue Fo'!D17)*'N25 Shuttle'!$B$4) -> 33375000 | C22: ='Fleet Ramp & Booking Revenue Fo'!D10 -> 65033240 | D22: =0.5*('Fleet Ramp & Booking Revenue Fo'!D5*C13+'Fleet Ramp & Booking Revenue Fo'!D6*E13)+0.5*'Fleet Ramp & Booking Revenue Fo'!D10*Assumptions!$B$15*Assumptions!$B$16*0.9 -> 20039547 | E22: =D22/B22 -> 0.60043588
A24: Rung 2: owned-fleet net at recaptured-take economics + platform take (90% margin) on the rest of the network.
A25: Rung 3: 50% of fleet net profit at recaptured-take economics + take on the other half of network GMV.

Sheet Marti Asset Holder P&L
A1: MARTI ASSET HOLDER P&L — IF MARTI OWNS VESSELS (2026–2030 FORECAST)
A2: Models Marti's own P&L if it chooses to own a tranche of the fleet, spread over the build-out — not just a single-year snapshot. Default below mirrors Rung 2 (the 20 launch N30s). Edit the blue input rows to test other ownership levels; everything else recalculates live off Marti Rollup, N30 Experience, and N25 Shuttle.
A4: OWNERSHIP INPUT (edit these — blue cells)
B5: 2026 | C5: 2027 | D5: 2028 | E5: 2029 | F5: 2030
A6: Marti-owned N30 Experience units | B6: 0 | C6: 10 | D6: 20 | E6: 20 | F6: 20
A7: Marti-owned N25 Shuttle units | B7: 0 | C7: 0 | D7: 0 | E7: 0 | F7: 0
A9: OWNED-FLEET ECONOMICS
A10: Owned-fleet GMV | B10: 0 | C10: =C6*'N30 Experience'!$C$24+C7*'N25 Shuttle'!$B$16 -> 11834200 | D10: =D6*'N30 Experience'!$C$24+D7*'N25 Shuttle'!$B$16 -> 23668400 | E10: =E6*'N30 Experience'!$C$24+E7*'N25 Shuttle'!$B$16 -> 23668400 | F10: =F6*'N30 Experience'!$C$24+F7*'N25 Shuttle'!$B$16 -> 23668400
A11: Net Navier Platform Fee (10% of owned GMV) | B11: 0 | C11: =-C10*Assumptions!$B$17 -> -1183420 | D11: =-D10*Assumptions!$B$17 -> -2366840 | E11: =-E10*Assumptions!$B$17 -> -2366840 | F11: =-F10*Assumptions!$B$17 -> -2366840
A12: Owned-fleet operating profit (net of Navier fee + direct opex) | B12: 0 | C12: =C6*'N30 Experience'!$C$35+C7*'N25 Shuttle'!$B$28 -> 7300676 | D12: =D6*'N30 Experience'!$C$35+D7*'N25 Shuttle'!$B$28 -> 14601352 | E12: =E6*'N30 Experience'!$C$35+E7*'N25 Shuttle'!$B$28 -> 14601352 | F12: =F6*'N30 Experience'!$C$35+F7*'N25 Shuttle'!$B$28 -> 14601352
A13: Depreciation (10-yr straight-line on owned-fleet capex) | B13: 0 | C13: =-(C6*'N30 Experience'!$B$4+C7*'N25 Shuttle'!$B$4)/10 -> -1000000 | D13: =-(D6*'N30 Experience'!$B$4+D7*'N25 Shuttle'!$B$4)/10 -> -2000000 | E13: =-(E6*'N30 Experience'!$B$4+E7*'N25 Shuttle'!$B$4)/10 -> -2000000 | F13: =-(F6*'N30 Experience'!$B$4+F7*'N25 Shuttle'!$B$4)/10 -> -2000000
A14: OWNED-FLEET NET PROFIT | B14: =B12+B13 -> 0 | C14: =C12+C13 -> 6300676 | D14: =D12+D13 -> 12601352 | E14: =E12+E13 -> 12601352 | F14: =F12+F13 -> 12601352
A15: Capex invested in owned fleet (book value) | B15: 0 | C15: =C6*'N30 Experience'!$B$4+C7*'N25 Shuttle'!$B$4 -> 10000000 | D15: =D6*'N30 Experience'!$B$4+D7*'N25 Shuttle'!$B$4 -> 20000000 | E15: =E6*'N30 Experience'!$B$4+E7*'N25 Shuttle'!$B$4 -> 20000000 | F15: =F6*'N30 Experience'!$B$4+F7*'N25 Shuttle'!$B$4 -> 20000000
A16: Annual ROIC (net profit / capex invested) | B16: n/a | C16: =C14/C15 -> 0.6300676 | D16: =D14/D15 -> 0.6300676 | E16: =E14/E15 -> 0.6300676 | F16: =F14/F15 -> 0.6300676
A18: MARTI'S TOTAL PROFIT — OWNERSHIP vs. PLATFORM-ONLY
A19: Booking take on rest of network (non-owned vessels, 75% × 15% × 90% margin) | B19: 0 | C19: =('Fleet Ramp & Booking Revenue Fo'!B10-C10)*Assumptions!$B$15*Assumptions!$B$16*0.9 -> 239642.55 | D19: =('Fleet Ramp & Booking Revenue Fo'!C10-D10)*Assumptions!$B$15*Assumptions!$B$16*0.9 -> 1297215 | E19: =('Fleet Ramp & Booking Revenue Fo'!D10-E10)*Assumptions!$B$15*Assumptions!$B$16*0.9 -> 4188190 | F19: =('Fleet Ramp & Booking Revenue Fo'!E10-F10)*Assumptions!$B$15*Assumptions!$B$16*0.9 -> 7220728.8
A20: TOTAL MARTI PROFIT — owns this tranche | B20: =B14+B19 -> 0 | C20: =C14+C19 -> 6540318.5 | D20: =D14+D19 -> 13898567 | E20: =E14+E19 -> 16789542 | F20: =F14+F19 -> 19822081
A21: MARTI PROFIT — platform-only (no ownership) | B21: 0 | C21: ='Fleet Ramp & Booking Revenue Fo'!B12*0.9 -> 1437855.3 | D21: ='Fleet Ramp & Booking Revenue Fo'!C12*0.9 -> 3693640.5 | E21: ='Fleet Ramp & Booking Revenue Fo'!D12*0.9 -> 6584615.5 | F21: ='Fleet Ramp & Booking Revenue Fo'!E12*0.9 -> 9617154.3
A22: Incremental profit from owning vs. platform-only | B22: =B20-B21 -> 0 | C22: =C20-C21 -> 5102463.2 | D22: =D20-D21 -> 10204926 | E22: =E20-E21 -> 10204926 | F22: =F20-F21 -> 10204926
A24: Cross-check: 2029 (col E) TOTAL MARTI PROFIT and platform-only profit above should tie to the Ownership tab's Rung 2 and Rung 1 net-profit figures (2029 snapshot).

Sheet Sensitivity
A1: PAYBACK SENSITIVITY GRIDS
A2: Grid 1 — N30 Experience: payback (yrs) vs realized $/day-equivalent × day-equivalents/yr. Target ≤ 1.0 yr.
A4: Realized $/day ↓ Day-equivalents → | B4: 120 | C4: 140 | D4: 160 | E4: 180 | F4: 200
A5: 3000 | B5: ='N30 Experience'!$B$4/($A5*B$4*(1-'N30 Experience'!$B$25-'N30 Experience'!$B$26)+'N30 Experience'!$B$34) -> 11.389522 | C5: ='N30 Experience'!$B$4/($A5*C$4*(1-'N30 Experience'!$B$25-'N30 Experience'!$B$26)+'N30 Experience'!$B$34) -> 7.4294205 | D5: ='N30 Experience'!$B$4/($A5*D$4*(1-'N30 Experience'!$B$25-'N30 Experience'!$B$26)+'N30 Experience'!$B$34) -> 5.5126792 | E5: ='N30 Experience'!$B$4/($A5*E$4*(1-'N30 Experience'!$B$25-'N30 Experience'!$B$26)+'N30 Experience'!$B$34) -> 4.3821209 | F5: ='N30 Experience'!$B$4/($A5*F$4*(1-'N30 Experience'!$B$25-'N30 Experience'!$B$26)+'N30 Experience'!$B$34) -> 3.6363636
A6: 3500 | B6: ='N30 Experience'!$B$4/($A6*B$4*(1-'N30 Experience'!$B$25-'N30 Experience'!$B$26)+'N30 Experience'!$B$34) -> 7.4294205 | C6: ='N30 Experience'!$B$4/($A6*C$4*(1-'N30 Experience'!$B$25-'N30 Experience'!$B$26)+'N30 Experience'!$B$34) -> 5.2854123 | D6: ='N30 Experience'!$B$4/($A6*D$4*(1-'N30 Experience'!$B$25-'N30 Experience'!$B$26)+'N30 Experience'!$B$34) -> 4.1017227 | E6: ='N30 Experience'!$B$4/($A6*E$4*(1-'N30 Experience'!$B$25-'N30 Experience'!$B$26)+'N30 Experience'!$B$34) -> 3.3512064 | F6: ='N30 Experience'!$B$4/($A6*F$4*(1-'N30 Experience'!$B$25-'N30 Experience'!$B$26)+'N30 Experience'!$B$34) -> 2.8328612
A7: 4000 | B7: ='N30 Experience'!$B$4/($A7*B$4*(1-'N30 Experience'!$B$25-'N30 Experience'!$B$26)+'N30 Experience'!$B$34) -> 5.5126792 | C7: ='N30 Experience'!$B$4/($A7*C$4*(1-'N30 Experience'!$B$25-'N30 Experience'!$B$26)+'N30 Experience'!$B$34) -> 4.1017227 | D7: ='N30 Experience'!$B$4/($A7*D$4*(1-'N30 Experience'!$B$25-'N30 Experience'!$B$26)+'N30 Experience'!$B$34) -> 3.2658393 | E7: ='N30 Experience'!$B$4/($A7*E$4*(1-'N30 Experience'!$B$25-'N30 Experience'!$B$26)+'N30 Experience'!$B$34) -> 2.712968 | F7: ='N30 Experience'!$B$4/($A7*F$4*(1-'N30 Experience'!$B$25-'N30 Experience'!$B$26)+'N30 Experience'!$B$34) -> 2.3201856
A8: 4500 | B8: ='N30 Experience'!$B$4/($A8*B$4*(1-'N30 Experience'!$B$25-'N30 Experience'!$B$26)+'N30 Experience'!$B$34) -> 4.3821209 | C8: ='N30 Experience'!$B$4/($A8*C$4*(1-'N30 Experience'!$B$25-'N30 Experience'!$B$26)+'N30 Experience'!$B$34) -> 3.3512064 | D8: ='N30 Experience'!$B$4/($A8*D$4*(1-'N30 Experience'!$B$25-'N30 Experience'!$B$26)+'N30 Experience'!$B$34) -> 2.712968 | E8: ='N30 Experience'!$B$4/($A8*E$4*(1-'N30 Experience'!$B$25-'N30 Experience'!$B$26)+'N30 Experience'!$B$34) -> 2.2789426 | F8: ='N30 Experience'!$B$4/($A8*F$4*(1-'N30 Experience'!$B$25-'N30 Experience'!$B$26)+'N30 Experience'!$B$34) -> 1.9646365
A9: 5000 | B9: ='N30 Experience'!$B$4/($A9*B$4*(1-'N30 Experience'!$B$25-'N30 Experience'!$B$26)+'N30 Experience'!$B$34) -> 3.6363636 | C9: ='N30 Experience'!$B$4/($A9*C$4*(1-'N30 Experience'!$B$25-'N30 Experience'!$B$26)+'N30 Experience'!$B$34) -> 2.8328612 | D9: ='N30 Experience'!$B$4/($A9*D$4*(1-'N30 Experience'!$B$25-'N30 Experience'!$B$26)+'N30 Experience'!$B$34) -> 2.3201856 | E9: ='N30 Experience'!$B$4/($A9*E$4*(1-'N30 Experience'!$B$25-'N30 Experience'!$B$26)+'N30 Experience'!$B$34) -> 1.9646365 | F9: ='N30 Experience'!$B$4/($A9*F$4*(1-'N30 Experience'!$B$25-'N30 Experience'!$B$26)+'N30 Experience'!$B$34) -> 1.7035775
A10: 5500 | B10: ='N30 Experience'!$B$4/($A10*B$4*(1-'N30 Experience'!$B$25-'N30 Experience'!$B$26)+'N30 Experience'!$B$34) -> 3.1075202 | C10: ='N30 Experience'!$B$4/($A10*C$4*(1-'N30 Experience'!$B$25-'N30 Experience'!$B$26)+'N30 Experience'!$B$34) -> 2.4533857 | D10: ='N30 Experience'!$B$4/($A10*D$4*(1-'N30 Experience'!$B$25-'N30 Experience'!$B$26)+'N30 Experience'!$B$34) -> 2.0267531 | E10: ='N30 Experience'!$B$4/($A10*E$4*(1-'N30 Experience'!$B$25-'N30 Experience'!$B$26)+'N30 Experience'!$B$34) -> 1.7265193 | F10: ='N30 Experience'!$B$4/($A10*F$4*(1-'N30 Experience'!$B$25-'N30 Experience'!$B$26)+'N30 Experience'!$B$34) -> 1.5037594
A11: 6000 | B11: ='N30 Experience'!$B$4/($A11*B$4*(1-'N30 Experience'!$B$25-'N30 Experience'!$B$26)+'N30 Experience'!$B$34) -> 2.712968 | C11: ='N30 Experience'!$B$4/($A11*C$4*(1-'N30 Experience'!$B$25-'N30 Experience'!$B$26)+'N30 Experience'!$B$34) -> 2.1635656 | D11: ='N30 Experience'!$B$4/($A11*D$4*(1-'N30 Experience'!$B$25-'N30 Experience'!$B$26)+'N30 Experience'!$B$34) -> 1.7992083 | E11: ='N30 Experience'!$B$4/($A11*E$4*(1-'N30 Experience'!$B$25-'N30 Experience'!$B$26)+'N30 Experience'!$B$34) -> 1.539883 | F11: ='N30 Experience'!$B$4/($A11*F$4*(1-'N30 Experience'!$B$25-'N30 Experience'!$B$26)+'N30 Experience'!$B$34) -> 1.345895
A12: 6500 | B12: ='N30 Experience'!$B$4/($A12*B$4*(1-'N30 Experience'!$B$25-'N30 Experience'!$B$26)+'N30 Experience'!$B$34) -> 2.4073182 | C12: ='N30 Experience'!$B$4/($A12*C$4*(1-'N30 Experience'!$B$25-'N30 Experience'!$B$26)+'N30 Experience'!$B$34) -> 1.9349845 | D12: ='N30 Experience'!$B$4/($A12*D$4*(1-'N30 Experience'!$B$25-'N30 Experience'!$B$26)+'N30 Experience'!$B$34) -> 1.6175995 | E12: ='N30 Experience'!$B$4/($A12*E$4*(1-'N30 Experience'!$B$25-'N30 Experience'!$B$26)+'N30 Experience'!$B$34) -> 1.3896609 | F12: ='N30 Experience'!$B$4/($A12*F$4*(1-'N30 Experience'!$B$25-'N30 Experience'!$B$26)+'N30 Experience'!$B$34) -> 1.2180268
A13: 7000 | B13: ='N30 Experience'!$B$4/($A13*B$4*(1-'N30 Experience'!$B$25-'N30 Experience'!$B$26)+'N30 Experience'!$B$34) -> 2.1635656 | C13: ='N30 Experience'!$B$4/($A13*C$4*(1-'N30 Experience'!$B$25-'N30 Experience'!$B$26)+'N30 Experience'!$B$34) -> 1.7500875 | D13: ='N30 Experience'!$B$4/($A13*D$4*(1-'N30 Experience'!$B$25-'N30 Experience'!$B$26)+'N30 Experience'!$B$34) -> 1.4692918 | E13: ='N30 Experience'!$B$4/($A13*E$4*(1-'N30 Experience'!$B$25-'N30 Experience'!$B$26)+'N30 Experience'!$B$34) -> 1.2661433 | F13: ='N30 Experience'!$B$4/($A13*F$4*(1-'N30 Experience'!$B$25-'N30 Experience'!$B$26)+'N30 Experience'!$B$34) -> 1.1123471
A16: Grid 2 — N25 Shuttle: payback (yrs) vs load factor × fare per seat. Target ≤ 1.5 yrs.
A17: Load ↓ Fare → | B17: 10 | C17: 12 | D17: 14 | E17: 16 | F17: 18
A18: 0.4 | B18: ='N25 Shuttle'!$B$4/((B$17*'N25 Shuttle'!$B$8*'N25 Shuttle'!$B$9*$A18*'N25 Shuttle'!$B$11+'N25 Shuttle'!$B$12*'N25 Shuttle'!$B$13)*(1-Assumptions!$B$17)+SUM('N25 Shuttle'!$B$19:$B$25)) -> 6.1035156 | C18: ='N25 Shuttle'!$B$4/((C$17*'N25 Shuttle'!$B$8*'N25 Shuttle'!$B$9*$A18*'N25 Shuttle'!$B$11+'N25 Shuttle'!$B$12*'N25 Shuttle'!$B$13)*(1-Assumptions!$B$17)+SUM('N25 Shuttle'!$B$19:$B$25)) -> 3.8371807 | D18: ='N25 Shuttle'!$B$4/((D$17*'N25 Shuttle'!$B$8*'N25 Shuttle'!$B$9*$A18*'N25 Shuttle'!$B$11+'N25 Shuttle'!$B$12*'N25 Shuttle'!$B$13)*(1-Assumptions!$B$17)+SUM('N25 Shuttle'!$B$19:$B$25)) -> 2.7981734 | E18: ='N25 Shuttle'!$B$4/((E$17*'N25 Shuttle'!$B$8*'N25 Shuttle'!$B$9*$A18*'N25 Shuttle'!$B$11+'N25 Shuttle'!$B$12*'N25 Shuttle'!$B$13)*(1-Assumptions!$B$17)+SUM('N25 Shuttle'!$B$19:$B$25)) -> 2.2019448 | F18: ='N25 Shuttle'!$B$4/((F$17*'N25 Shuttle'!$B$8*'N25 Shuttle'!$B$9*$A18*'N25 Shuttle'!$B$11+'N25 Shuttle'!$B$12*'N25 Shuttle'!$B$13)*(1-Assumptions!$B$17)+SUM('N25 Shuttle'!$B$19:$B$25)) -> 1.8151719
A19: 0.45 | B19: ='N25 Shuttle'!$B$4/((B$17*'N25 Shuttle'!$B$8*'N25 Shuttle'!$B$9*$A19*'N25 Shuttle'!$B$11+'N25 Shuttle'!$B$12*'N25 Shuttle'!$B$13)*(1-Assumptions!$B$17)+SUM('N25 Shuttle'!$B$19:$B$25)) -> 4.4579173 | C19: ='N25 Shuttle'!$B$4/((C$17*'N25 Shuttle'!$B$8*'N25 Shuttle'!$B$9*$A19*'N25 Shuttle'!$B$11+'N25 Shuttle'!$B$12*'N25 Shuttle'!$B$13)*(1-Assumptions!$B$17)+SUM('N25 Shuttle'!$B$19:$B$25)) -> 3.0013446 | D19: ='N25 Shuttle'!$B$4/((D$17*'N25 Shuttle'!$B$8*'N25 Shuttle'!$B$9*$A19*'N25 Shuttle'!$B$11+'N25 Shuttle'!$B$12*'N25 Shuttle'!$B$13)*(1-Assumptions!$B$17)+SUM('N25 Shuttle'!$B$19:$B$25)) -> 2.2621978 | E19: ='N25 Shuttle'!$B$4/((E$17*'N25 Shuttle'!$B$8*'N25 Shuttle'!$B$9*$A19*'N25 Shuttle'!$B$11+'N25 Shuttle'!$B$12*'N25 Shuttle'!$B$13)*(1-Assumptions!$B$17)+SUM('N25 Shuttle'!$B$19:$B$25)) -> 1.8151719 | F19: ='N25 Shuttle'!$B$4/((F$17*'N25 Shuttle'!$B$8*'N25 Shuttle'!$B$9*$A19*'N25 Shuttle'!$B$11+'N25 Shuttle'!$B$12*'N25 Shuttle'!$B$13)*(1-Assumptions!$B$17)+SUM('N25 Shuttle'!$B$19:$B$25)) -> 1.5156659
A20: 0.5 | B20: ='N25 Shuttle'!$B$4/((B$17*'N25 Shuttle'!$B$8*'N25 Shuttle'!$B$9*$A20*'N25 Shuttle'!$B$11+'N25 Shuttle'!$B$12*'N25 Shuttle'!$B$13)*(1-Assumptions!$B$17)+SUM('N25 Shuttle'!$B$19:$B$25)) -> 3.511236 | C20: ='N25 Shuttle'!$B$4/((C$17*'N25 Shuttle'!$B$8*'N25 Shuttle'!$B$9*$A20*'N25 Shuttle'!$B$11+'N25 Shuttle'!$B$12*'N25 Shuttle'!$B$13)*(1-Assumptions!$B$17)+SUM('N25 Shuttle'!$B$19:$B$25)) -> 2.464511 | D20: ='N25 Shuttle'!$B$4/((D$17*'N25 Shuttle'!$B$8*'N25 Shuttle'!$B$9*$A20*'N25 Shuttle'!$B$11+'N25 Shuttle'!$B$12*'N25 Shuttle'!$B$13)*(1-Assumptions!$B$17)+SUM('N25 Shuttle'!$B$19:$B$25)) -> 1.8985419 | E20: ='N25 Shuttle'!$B$4/((E$17*'N25 Shuttle'!$B$8*'N25 Shuttle'!$B$9*$A20*'N25 Shuttle'!$B$11+'N25 Shuttle'!$B$12*'N25 Shuttle'!$B$13)*(1-Assumptions!$B$17)+SUM('N25 Shuttle'!$B$19:$B$25)) -> 1.5439723 | F20: ='N25 Shuttle'!$B$4/((F$17*'N25 Shuttle'!$B$8*'N25 Shuttle'!$B$9*$A20*'N25 Shuttle'!$B$11+'N25 Shuttle'!$B$12*'N25 Shuttle'!$B$13)*(1-Assumptions!$B$17)+SUM('N25 Shuttle'!$B$19:$B$25)) -> 1.3009992
A21: 0.55 | B21: ='N25 Shuttle'!$B$4/((B$17*'N25 Shuttle'!$B$8*'N25 Shuttle'!$B$9*$A21*'N25 Shuttle'!$B$11+'N25 Shuttle'!$B$12*'N25 Shuttle'!$B$13)*(1-Assumptions!$B$17)+SUM('N25 Shuttle'!$B$19:$B$25)) -> 2.8962002 | C21: ='N25 Shuttle'!$B$4/((C$17*'N25 Shuttle'!$B$8*'N25 Shuttle'!$B$9*$A21*'N25 Shuttle'!$B$11+'N25 Shuttle'!$B$12*'N25 Shuttle'!$B$13)*(1-Assumptions!$B$17)+SUM('N25 Shuttle'!$B$19:$B$25)) -> 2.0905807 | D21: ='N25 Shuttle'!$B$4/((D$17*'N25 Shuttle'!$B$8*'N25 Shuttle'!$B$9*$A21*'N25 Shuttle'!$B$11+'N25 Shuttle'!$B$12*'N25 Shuttle'!$B$13)*(1-Assumptions!$B$17)+SUM('N25 Shuttle'!$B$19:$B$25)) -> 1.6356118 | E21: ='N25 Shuttle'!$B$4/((E$17*'N25 Shuttle'!$B$8*'N25 Shuttle'!$B$9*$A21*'N25 Shuttle'!$B$11+'N25 Shuttle'!$B$12*'N25 Shuttle'!$B$13)*(1-Assumptions!$B$17)+SUM('N25 Shuttle'!$B$19:$B$25)) -> 1.3432772 | F21: ='N25 Shuttle'!$B$4/((F$17*'N25 Shuttle'!$B$8*'N25 Shuttle'!$B$9*$A21*'N25 Shuttle'!$B$11+'N25 Shuttle'!$B$12*'N25 Shuttle'!$B$13)*(1-Assumptions!$B$17)+SUM('N25 Shuttle'!$B$19:$B$25)) -> 1.1395959
A22: 0.6 | B22: ='N25 Shuttle'!$B$4/((B$17*'N25 Shuttle'!$B$8*'N25 Shuttle'!$B$9*$A22*'N25 Shuttle'!$B$11+'N25 Shuttle'!$B$12*'N25 Shuttle'!$B$13)*(1-Assumptions!$B$17)+SUM('N25 Shuttle'!$B$19:$B$25)) -> 2.464511 | C22: ='N25 Shuttle'!$B$4/((C$17*'N25 Shuttle'!$B$8*'N25 Shuttle'!$B$9*$A22*'N25 Shuttle'!$B$11+'N25 Shuttle'!$B$12*'N25 Shuttle'!$B$13)*(1-Assumptions!$B$17)+SUM('N25 Shuttle'!$B$19:$B$25)) -> 1.8151719 | D22: ='N25 Shuttle'!$B$4/((D$17*'N25 Shuttle'!$B$8*'N25 Shuttle'!$B$9*$A22*'N25 Shuttle'!$B$11+'N25 Shuttle'!$B$12*'N25 Shuttle'!$B$13)*(1-Assumptions!$B$17)+SUM('N25 Shuttle'!$B$19:$B$25)) -> 1.4366495 | E22: ='N25 Shuttle'!$B$4/((E$17*'N25 Shuttle'!$B$8*'N25 Shuttle'!$B$9*$A22*'N25 Shuttle'!$B$11+'N25 Shuttle'!$B$12*'N25 Shuttle'!$B$13)*(1-Assumptions!$B$17)+SUM('N25 Shuttle'!$B$19:$B$25)) -> 1.1887553 | F22: ='N25 Shuttle'!$B$4/((F$17*'N25 Shuttle'!$B$8*'N25 Shuttle'!$B$9*$A22*'N25 Shuttle'!$B$11+'N25 Shuttle'!$B$12*'N25 Shuttle'!$B$13)*(1-Assumptions!$B$17)+SUM('N25 Shuttle'!$B$19:$B$25)) -> 1.0138204
A23: 0.65 | B23: ='N25 Shuttle'!$B$4/((B$17*'N25 Shuttle'!$B$8*'N25 Shuttle'!$B$9*$A23*'N25 Shuttle'!$B$11+'N25 Shuttle'!$B$12*'N25 Shuttle'!$B$13)*(1-Assumptions!$B$17)+SUM('N25 Shuttle'!$B$19:$B$25)) -> 2.1448181 | C23: ='N25 Shuttle'!$B$4/((C$17*'N25 Shuttle'!$B$8*'N25 Shuttle'!$B$9*$A23*'N25 Shuttle'!$B$11+'N25 Shuttle'!$B$12*'N25 Shuttle'!$B$13)*(1-Assumptions!$B$17)+SUM('N25 Shuttle'!$B$19:$B$25)) -> 1.6038801 | D23: ='N25 Shuttle'!$B$4/((D$17*'N25 Shuttle'!$B$8*'N25 Shuttle'!$B$9*$A23*'N25 Shuttle'!$B$11+'N25 Shuttle'!$B$12*'N25 Shuttle'!$B$13)*(1-Assumptions!$B$17)+SUM('N25 Shuttle'!$B$19:$B$25)) -> 1.2808427 | E23: ='N25 Shuttle'!$B$4/((E$17*'N25 Shuttle'!$B$8*'N25 Shuttle'!$B$9*$A23*'N25 Shuttle'!$B$11+'N25 Shuttle'!$B$12*'N25 Shuttle'!$B$13)*(1-Assumptions!$B$17)+SUM('N25 Shuttle'!$B$19:$B$25)) -> 1.0661163 | F23: ='N25 Shuttle'!$B$4/((F$17*'N25 Shuttle'!$B$8*'N25 Shuttle'!$B$9*$A23*'N25 Shuttle'!$B$11+'N25 Shuttle'!$B$12*'N25 Shuttle'!$B$13)*(1-Assumptions!$B$17)+SUM('N25 Shuttle'!$B$19:$B$25)) -> 0.91304856
A24: 0.7 | B24: ='N25 Shuttle'!$B$4/((B$17*'N25 Shuttle'!$B$8*'N25 Shuttle'!$B$9*$A24*'N25 Shuttle'!$B$11+'N25 Shuttle'!$B$12*'N25 Shuttle'!$B$13)*(1-Assumptions!$B$17)+SUM('N25 Shuttle'!$B$19:$B$25)) -> 1.8985419 | C24: ='N25 Shuttle'!$B$4/((C$17*'N25 Shuttle'!$B$8*'N25 Shuttle'!$B$9*$A24*'N25 Shuttle'!$B$11+'N25 Shuttle'!$B$12*'N25 Shuttle'!$B$13)*(1-Assumptions!$B$17)+SUM('N25 Shuttle'!$B$19:$B$25)) -> 1.4366495 | D24: ='N25 Shuttle'!$B$4/((D$17*'N25 Shuttle'!$B$8*'N25 Shuttle'!$B$9*$A24*'N25 Shuttle'!$B$11+'N25 Shuttle'!$B$12*'N25 Shuttle'!$B$13)*(1-Assumptions!$B$17)+SUM('N25 Shuttle'!$B$19:$B$25)) -> 1.1555243 | E24: ='N25 Shuttle'!$B$4/((E$17*'N25 Shuttle'!$B$8*'N25 Shuttle'!$B$9*$A24*'N25 Shuttle'!$B$11+'N25 Shuttle'!$B$12*'N25 Shuttle'!$B$13)*(1-Assumptions!$B$17)+SUM('N25 Shuttle'!$B$19:$B$25)) -> 0.96641514 | F24: ='N25 Shuttle'!$B$4/((F$17*'N25 Shuttle'!$B$8*'N25 Shuttle'!$B$9*$A24*'N25 Shuttle'!$B$11+'N25 Shuttle'!$B$12*'N25 Shuttle'!$B$13)*(1-Assumptions!$B$17)+SUM('N25 Shuttle'!$B$19:$B$25)) -> 0.83049856
A27: Grid 3 — ASSET-HOLDER (N30 3rd-party owner) payback (yrs) vs Marti take rate × revenue scenario
A28: Marti take rate ↓ / Scenario → | B28: Aggressive | C28: Moderate | D28: Conservative
A29: 0.1 | B29: ='N30 Experience'!$B$4/(('N30 Experience'!$E$13*'N30 Experience'!$C$20*Assumptions!$B$25)*(1-'N30 Experience'!$B$25-'N30 Experience'!$B$26)+'N30 Experience'!$B$34-('N30 Experience'!$E$13*'N30 Experience'!$C$20*Assumptions!$B$25)*Assumptions!$B$15*$A29) -> 1.5593056 | C29: ='N30 Experience'!$B$4/(('N30 Experience'!$E$13*'N30 Experience'!$C$20*Assumptions!$B$26)*(1-'N30 Experience'!$B$25-'N30 Experience'!$B$26)+'N30 Experience'!$B$34-('N30 Experience'!$E$13*'N30 Experience'!$C$20*Assumptions!$B$26)*Assumptions!$B$15*$A29) -> 2.310892 | D29: ='N30 Experience'!$B$4/(('N30 Experience'!$E$13*'N30 Experience'!$C$20*Assumptions!$B$27)*(1-'N30 Experience'!$B$25-'N30 Experience'!$B$26)+'N30 Experience'!$B$34-('N30 Experience'!$E$13*'N30 Experience'!$C$20*Assumptions!$B$27)*Assumptions!$B$15*$A29) -> 3.7612211
A30: 0.15 | B30: ='N30 Experience'!$B$4/(('N30 Experience'!$E$13*'N30 Experience'!$C$20*Assumptions!$B$25)*(1-'N30 Experience'!$B$25-'N30 Experience'!$B$26)+'N30 Experience'!$B$34-('N30 Experience'!$E$13*'N30 Experience'!$C$20*Assumptions!$B$25)*Assumptions!$B$15*$A30) -> 1.6752303 | C30: ='N30 Experience'!$B$4/(('N30 Experience'!$E$13*'N30 Experience'!$C$20*Assumptions!$B$26)*(1-'N30 Experience'!$B$25-'N30 Experience'!$B$26)+'N30 Experience'!$B$34-('N30 Experience'!$E$13*'N30 Experience'!$C$20*Assumptions!$B$26)*Assumptions!$B$15*$A30) -> 2.5034445 | D30: ='N30 Experience'!$B$4/(('N30 Experience'!$E$13*'N30 Experience'!$C$20*Assumptions!$B$27)*(1-'N30 Experience'!$B$25-'N30 Experience'!$B$26)+'N30 Experience'!$B$34-('N30 Experience'!$E$13*'N30 Experience'!$C$20*Assumptions!$B$27)*Assumptions!$B$15*$A30) -> 4.1414201
A31: 0.2 | B31: ='N30 Experience'!$B$4/(('N30 Experience'!$E$13*'N30 Experience'!$C$20*Assumptions!$B$25)*(1-'N30 Experience'!$B$25-'N30 Experience'!$B$26)+'N30 Experience'!$B$34-('N30 Experience'!$E$13*'N30 Experience'!$C$20*Assumptions!$B$25)*Assumptions!$B$15*$A31) -> 1.8097759 | C31: ='N30 Experience'!$B$4/(('N30 Experience'!$E$13*'N30 Experience'!$C$20*Assumptions!$B$26)*(1-'N30 Experience'!$B$25-'N30 Experience'!$B$26)+'N30 Experience'!$B$34-('N30 Experience'!$E$13*'N30 Experience'!$C$20*Assumptions!$B$26)*Assumptions!$B$15*$A31) -> 2.7310022 | D31: ='N30 Experience'!$B$4/(('N30 Experience'!$E$13*'N30 Experience'!$C$20*Assumptions!$B$27)*(1-'N30 Experience'!$B$25-'N30 Experience'!$B$26)+'N30 Experience'!$B$34-('N30 Experience'!$E$13*'N30 Experience'!$C$20*Assumptions!$B$27)*Assumptions!$B$15*$A31) -> 4.6071266
A32: 0.25 | B32: ='N30 Experience'!$B$4/(('N30 Experience'!$E$13*'N30 Experience'!$C$20*Assumptions!$B$25)*(1-'N30 Experience'!$B$25-'N30 Experience'!$B$26)+'N30 Experience'!$B$34-('N30 Experience'!$E$13*'N30 Experience'!$C$20*Assumptions!$B$25)*Assumptions!$B$15*$A32) -> 1.9678208 | C32: ='N30 Experience'!$B$4/(('N30 Experience'!$E$13*'N30 Experience'!$C$20*Assumptions!$B$26)*(1-'N30 Experience'!$B$25-'N30 Experience'!$B$26)+'N30 Experience'!$B$34-('N30 Experience'!$E$13*'N30 Experience'!$C$20*Assumptions!$B$26)*Assumptions!$B$15*$A32) -> 3.0040651 | D32: ='N30 Experience'!$B$4/(('N30 Experience'!$E$13*'N30 Experience'!$C$20*Assumptions!$B$27)*(1-'N30 Experience'!$B$25-'N30 Experience'!$B$26)+'N30 Experience'!$B$34-('N30 Experience'!$E$13*'N30 Experience'!$C$20*Assumptions!$B$27)*Assumptions!$B$15*$A32) -> 5.1908415
A33: 0.3 | B33: ='N30 Experience'!$B$4/(('N30 Experience'!$E$13*'N30 Experience'!$C$20*Assumptions!$B$25)*(1-'N30 Experience'!$B$25-'N30 Experience'!$B$26)+'N30 Experience'!$B$34-('N30 Experience'!$E$13*'N30 Experience'!$C$20*Assumptions!$B$25)*Assumptions!$B$15*$A33) -> 2.1561106 | C33: ='N30 Experience'!$B$4/(('N30 Experience'!$E$13*'N30 Experience'!$C$20*Assumptions!$B$26)*(1-'N30 Experience'!$B$25-'N30 Experience'!$B$26)+'N30 Experience'!$B$34-('N30 Experience'!$E$13*'N30 Experience'!$C$20*Assumptions!$B$26)*Assumptions!$B$15*$A33) -> 3.3377996 | D33: ='N30 Experience'!$B$4/(('N30 Experience'!$E$13*'N30 Experience'!$C$20*Assumptions!$B$27)*(1-'N30 Experience'!$B$25-'N30 Experience'!$B$26)+'N30 Experience'!$B$34-('N30 Experience'!$E$13*'N30 Experience'!$C$20*Assumptions!$B$27)*Assumptions!$B$15*$A33) -> 5.9439266
A34: Green ≤ target payback (acceptable); red = asset holder underwater on timeline. Marti’s proposed take = 30% (bottom row).
A35: Acceptable payback target (yrs): | B35: 4
A37: MARTI NEGOTIATION READOUT — asset holder must clear ≤ target payback
A38: Asset-holder payback at Marti’s proposed 30% take:
A39: Aggressive | B39: =B33 -> 2.1561106
A40: Moderate | B40: =C33 -> 3.3377996
A41: Conservative | B41: =D33 -> 5.9439266
A43: Lever 1 — LOWER TAKE: max Marti take rate for ≤ target payback:
A44: Aggressive | B44: =(('N30 Experience'!$E$13*'N30 Experience'!$C$20*Assumptions!$B$25)*(1-'N30 Experience'!$B$25-'N30 Experience'!$B$26)+'N30 Experience'!$B$34-'N30 Experience'!$B$4/$B$35)/(('N30 Experience'!$E$13*'N30 Experience'!$C$20*Assumptions!$B$25)*Assumptions!$B$15) -> 0.54088163
A45: Moderate | B45: =(('N30 Experience'!$E$13*'N30 Experience'!$C$20*Assumptions!$B$26)*(1-'N30 Experience'!$B$25-'N30 Experience'!$B$26)+'N30 Experience'!$B$34-'N30 Experience'!$B$4/$B$35)/(('N30 Experience'!$E$13*'N30 Experience'!$C$20*Assumptions!$B$26)*Assumptions!$B$15) -> 0.37450883
A46: Conservative (binding) | B46: =(('N30 Experience'!$E$13*'N30 Experience'!$C$20*Assumptions!$B$27)*(1-'N30 Experience'!$B$25-'N30 Experience'!$B$26)+'N30 Experience'!$B$34-'N30 Experience'!$B$4/$B$35)/(('N30 Experience'!$E$13*'N30 Experience'!$C$20*Assumptions!$B$27)*Assumptions!$B$15) -> 0.13251205
A48: Lever 2 — REVENUE GUARANTEE (take held at 30%): min gross revenue / N30 Marti must guarantee for ≤ target payback:
...

Sheet 2026 Validation
A1: 2026 DEMAND VALIDATION
A2: Navier operates only Navier vessels, ever. 2026 proves demand through data, commitments, and deposits — not by building charter aggregation.
A4: TRACK 1 — MARTI DATA-SHARING CLAUSE (MOU term)
A5: Waterfront O/D corridors mapped from Marti ride heatmaps | B5: 12
A6: Pier-adjacent trip density & time-of-day patterns | B6: quarterly data drops
A7: Purpose | B7: corridor selection + fare elasticity priors before any hull ships
A9: TRACK 2 — HOTEL LOIs (Tier 1 / 1.5 waterfront properties)
A10: LOIs targeted by MOU signing + 6 months | B10: 6
A11: Dedicated-boat interest per LOI (avg units) | B11: 1.5
A12: Implied committed hull demand (units) | B12: =ROUNDUP(B10*B11,0) -> 9
A13: vs. 10-boat launch fleet | B13: =B12/10 -> 0.9
A15: TRACK 3 — DEPOSIT-BACKED WAITLIST (announcement + app)
A16: Waitlist sign-ups target | B16: 2500
A17: Refundable deposit | B17: 100
A18: Escrowed demand signal | B18: =B16*B17 -> 250000
A19: Launch-quarter conversion assumption | B19: 0.4
A20: Converted bookings, launch quarter | B20: =B16*B19 -> 1000
A21: Implied bookings/day/boat from waitlist alone (10 boats, 90 days) | B21: =B20/(10*90) -> 1.1111111
A22: vs. 5 slots/day capacity | B22: =B21/5 -> 0.22222222
A24: TRACK 4 — DEMOS (no hulls in Türkiye before Mar 2027)
A25: International demos (Abu Dhabi / San Francisco / New York) | B25: 3
A26: Purpose | B26: Marti leadership + candidate asset holders + Tier 1 hotel principals on the water
A28: MOU KEY TERMS (to accompany validation program)
A29: Bidirectional exclusivity (yrs) | B29: 4
A30: Marti side: water mobility vertical = Navier network exclusively (no other vessel suppliers, no charter aggregation)
A31: Navier side: Marti = exclusive third-party demand platform in Türkiye (carve-outs: Navier app, hotel direct, corporate accounts)
A32: Performance gates: Marti keeps exclusivity via marketing/volume commitments; Navier keeps it via fleet milestones (10 by Mar-27, 100 by end-29)
A33: Data ownership: all booking & operational data generated through the Navier layer is owned by Navier; Marti receives aggregated insights
